<?xml version="1.0"?>
<robot xmlns:xacro="http://www.ros.org/wiki/xacro" name="mybot">

  <xacro:property name="base_width" value="0.1"/>
  <xacro:property name="base_len" value="0.2"/>
  <xacro:property name="base_height" value="0.03"/>
  <xacro:property name="wheel_radius" value="0.03"/>
  <xacro:property name="base_wheel_gap" value="0.005"/>
  <xacro:property name="wheel_separation" value="0.2"/>

  <xacro:property name="caster_wheel_radius" value="0.01"/>
  <xacro:property name="caster_wheel_mass" value="1"/>
  <xacro:property name="wheel_mass" value="1"/>
  <xacro:property name="base_mass" value="5"/>

  <!--Color Properties-->
  <material name="blue">
    <color rgba="0 0 0.8 1"/>
  </material>
  <material name="red">
    <color rgba="0.8 0.0 0.0 1.0"/>
  </material>
  <material name="orange">
    <color rgba="0.82 0.32 0.0 1"/>
  </material>
  <material name="green">
    <color rgba="0.12 0.70 0.0 1"/>
  </material>

  <!--Interial macros-->
  <xacro:macro name="cylinder_inertia" params="m r h">
    <inertial>
      <mass value="${m}"/>
      <inertia ixx="${m*(3*r*r+h*h)/12}" ixy = "0" ixz = "0" iyy="${m*(3*r*r+h*h)/12}" iyz = "0" izz="${m*r*r/2}"/> 
    </inertial>
  </xacro:macro>

  <xacro:macro name="box_inertia" params="m w h d">
    <inertial>
      <mass value="${m}"/>
      <inertia ixx="${m / 12.0 * (d*d + h*h)}" ixy="0.0" ixz="0.0" iyy="${m / 12.0 * (w*w + h*h)}" iyz="0.0" izz="${m / 12.0 * (w*w + d*d)}"/>
    </inertial>
  </xacro:macro>

  <xacro:macro name="sphere_inertia" params="m r">
    <inertial>
      <mass value="${m}"/>
      <inertia ixx="${2.0*m*(r*r)/5.0}" ixy="0.0" ixz="0.0" iyy="${2.0*m*(r*r)/5.0}" iyz="0.0" izz="${2.0*m*(r*r)/5.0}"/>
    </inertial>
  </xacro:macro>


  <!--Base Footprint-->
  <link name="base_footprint">
    <!--xacro:box_inertia m="10" w="0.001" h="0.001" d="0.001"/-->
    <visual>
        <origin xyz="0 0 0" rpy="0 0 0" />
        <geometry>
            <box size="0.001 0.001 0.001" />
        </geometry>
    </visual>
  </link>

  <!--Base link-->
  <link name="base_link">
    <xacro:box_inertia m="${base_mass}" w="${base_len}" h="${base_width}" d="${base_height}"/>
    <visual>
      <origin xyz="0 0 0.035" rpy="0 0 0" />
      <geometry>
        <box size="${base_len} ${base_width} ${base_height}"/>
      </geometry>
      <material name="orange"/>
    </visual>
    <collision>
      <geometry>
        <box size="${base_len} ${base_width} ${base_height}"/>
      </geometry>
    </collision>
  </link>

  <!--base_link to base_footprint Joint-->
  <joint name="base_link_joint" type="fixed">
    <origin xyz="0 0 0" rpy="0 0 0" />
    <parent link="base_footprint"/>
    <child link="base_link" />
  </joint>

  <!--Caster Wheel Link-->
  <link name="caster_wheel">
    <visual>
      <origin xyz="0.03 0 0.005" rpy="0 0 0"/>
      <geometry>
        <sphere radius="${caster_wheel_radius}"/>
      </geometry>
      <material name="blue"/>
    </visual>
    <collision>
      <origin xyz="0.03 0 0.005" rpy="0 0 0"/>
      <geometry>
        <sphere radius="${caster_wheel_radius}"/>
      </geometry>
    </collision>
    <xacro:sphere_inertia m="${caster_wheel_mass}" r="${caster_wheel_radius}"/>
  </link>

  <!--Caster Wheel Joint-->
  <joint name="caster_wheel_joint" type="continuous">
    <axis xyz="0 1 0" rpy="0 0 0" />
    <parent link="base_link"/>
    <child link="caster_wheel"/>
    <origin xyz="0.03 0 0.005" rpy="0 0 0"/>
  </joint>

    <!--Wheel link & joint macro-->
  <xacro:macro name="wheel" params="prefix reflect">
    <link name="${prefix}_wheel">
      <visual>
        <origin xyz="-0.015 0 0.015" rpy="${pi/2} 0 0"/>
        <geometry>
          <cylinder radius="${wheel_radius}" length="0.005"/>
        </geometry>
        <material name="blue"/>
      </visual>
      <collision>
        <origin xyz="0 0 0" rpy="${pi/2} 0 0"/>
        <geometry>
          <cylinder radius="${wheel_radius}" length="0.005"/>
        </geometry>
      </collision>
      <xacro:cylinder_inertia m="${wheel_mass}" r="${wheel_radius}" h="0.005"/>
    </link>

    <joint name="${prefix}_wheel_joint" type="continuous">
      <axis xyz="-0.06 1 0" rpy="0 0 0" />
      <parent link="base_link"/>
      <child link="${prefix}_wheel"/>
      <origin xyz="-0.015 ${((base_width/2)+base_wheel_gap)*reflect} 0.015" rpy="0 0 0"/>
    </joint>
  </xacro:macro>

  <!--Create Left & Right Back Wheel links/joints-->
  <xacro:wheel prefix="left_back" reflect="1"/>
  <xacro:wheel prefix="right_back" reflect="-1"/>

</robot>